Workbook
Name NativeTimeline_List_Date: #N/A
Name Slicer_FROM_1000_1500: #N/A
Name Slicer_FROM_1500_2000: #N/A
Name Slicer_GRP_BY_50: #N/A
Name Slicer_GRP_BY_50IN_500: #N/A
Name Slicer_grp_by_Listing: #N/A
Name Slicer_grp_by_Listing1: #N/A
Name Slicer_grp_by_Listing2: #N/A
Name Slicer_Grp_by_total: #N/A
Name Slicer_Grp_by_total1: #N/A
Name Slicer_Grp_by_total2: #N/A
Name Slicer_IPO_NAME: #N/A
Name Slicer_Postive: #N/A
Name Slicer_Size_grp: #N/A
Name Slicer_Size_grp2: #N/A
Name Slicer_Size_grp21: #N/A
Name Slicer_Year: #N/A
Name Slicer_Year1: #N/A

Sheet Total_vs_Gains
A3: IPO NAME | B3: Total SuCcription | C3: Sum of Listing Gains(%) | D3: Gains(%) | E3: Count of IPO NAME | H3: =GETPIVOTDATA("Count of IPO NAME",Total_vs_Gains!$A$3) -> 6
A4: Borana Weaves Ltd | B4: 148.78 | C4: 12.5 | D4: 12.5 | E4: 1 | R4: Row Labels | S4: Sum of Issue size divide by 10 | T4: Sum of Listing Gains(%) | U4: Count of First name
A5: Exicom Tele-System | B5: 129.54 | C5: 85.92 | D5: 85.92 | E5: 1 | G5: {=MAX(0, SUMPRODUCT( SUBTOTAL(103, OFFSET(Total_vs_Gains!$C$4, ROW($C$4:$C$306)-ROW(Total_vs_Gains!$C$4), 0, 1)) * --(ISNUMBER($C$4:$C$306)) * --($C$4:$C$306 > 0) ) ) - 1} -> 6 | R5: Uma Exports Ltd | S5: 6 | T5: 17.65 | U5: 1
A6: GNG Electronics Lt | B6: 147.93 | C6: 47.68 | D6: 47.68 | E6: 1 | R6: Udayshivakumar Inf | S6: 6.6 | T6: 0 | U6: 1
A7: Go Fashion (India) | B7: 135.46 | C7: 90.72 | D7: 90.72 | E7: 1 | R7: Sah Polymers Ltd | S7: 6.63 | T7: 30.77 | U7: 1
A8: Mukka Proteins Ltd | B8: 136.99 | C8: 57.14 | D8: 57.14 | E8: 1 | R8: Plaza Wires Ltd | S8: 7.128 | T8: 55.56 | U8: 1
A9: Rolex Rings Ltd | B9: 130.44 | C9: 38.78 | D9: 38.78 | E9: 1 | R9: Vibhor Steel Tubes | S9: 7.217 | T9: 178.81 | U9: 1
A10: Grand Total | B10: 829.14 | C10: 332.74 | D10: 332.74 | E10: 6 | H10: Z | R10: Nureca Ltd | S10: 10 | T10: 58.74 | U10: 1
R11: RBZ Jewellers Ltd | S11: 10 | T11: 0 | U11: 1
R12: Globe Civil Projec | S12: 11.9 | T12: 28.31 | U12: 1
R13: Sigachi Industries | S13: 12.543 | T13: 252.76 | U13: 1
R14: HP Adhesives Ltd | S14: 12.596 | T14: 16.42 | U14: 1
R15: Highway Infrastruc | S15: 13 | T15: 67.14 | U15: 1
R16: Hariom Pipe Indust | S16: 13.005 | T16: 39.87 | U16: 1
R17: Kronox Lab Science | S17: 13.015 | T17: 21.32 | U17: 1
R18: SRM Contractors Lt | S18: 13.02 | T18: 7.14 | U18: 1
R19: Akme Fintrade (Ind | S19: 13.2 | T19: 4.75 | U19: 1
R20: Nova Agritech Ltd | S20: 14.381 | T20: 36.59 | U20: 1
R21: Borana Weaves Ltd | S21: 14.489 | T21: 12.5 | U21: 1
R22: Manba Finance Ltd | S22: 15.084 | T22: 25 | U22: 1
... R36: Vraj Iron & Steel | S36: 17.1 | T36: 15.94 | U36: 1
R37: Mamata Machinery L | S37: 17.935 | T37: 146.91 | U37: 1 | X37: POSITIVE AGINS | Z37: NEGATIVE GAINS | AB37: NO GAINS
J38: NEGATVE GAINS | K38: NEUTRAL AGAIN | R38: Stallion India Flu | S38: 19.945 | T38: 33.33 | U38: 1 | Z38: {=MAX(0, SUMPRODUCT( SUBTOTAL(103,OFFSET($T$4,ROW($C$4:$T$306)-ROW($T$4),0,1))* --(ISNUMBER($T$4:$T$306))* --($T$4:$T$306<0) ))} -> 11 | AB38: {=MAX(0, SUMPRODUCT( SUBTOTAL(103,OFFSET($T$4,ROW($T$4:$T$306)-ROW($T$4),0,1))* --(ISNUMBER($T$4:$T$306))* --($T$4:$T$306=0) ))} -> 7
J39: {=MAX(0, SUMPRODUCT( SUBTOTAL(103,OFFSET(Total_vs_Gains!$C$4,ROW($C$4:$C$306)-ROW(Total_vs_Gains!$C$4),0,1))* --(ISNUMBER($C$4:$C$306))* --($C$4:$C$306<0) ))} -> 0 | K39: {=MAX(0, SUMPRODUCT( SUBTOTAL(103, OFFSET(Total_vs_Gains!$C$4, ROW($C$4:$C$306)-ROW(Total_vs_Gains!$C$4), 0, 1)) * --(ISNUMBER($C$4:$C$306)) * --($C$4:$C$306 = 0) ) )} -> 0 | R39: Veranda Learning S | S39: 20 | T39: 14.6 | U39: 1
R40: Indogulf Cropscien | S40: 20 | T40: 0 | U40: 1
K41: Average | R41: Orient Technologie | S41: 21.476 | T41: 40.78 | U41: 1 | Y41: Average gains
R42: Scoda Tubes Ltd | S42: 22 | T42: 0 | U42: 1 | Y42: =GETPIVOTDATA("Sum of Listing Gains(%)",$R$4)/GETPIVOTDATA("Count of First name",$R$4) -> 31.582706
K43: =(GETPIVOTDATA("Gains(%)",Total_vs_Gains!$A$3)/GETPIVOTDATA("Count of IPO NAME",Total_vs_Gains!$A$3)) -> 55.456667 | R43: Denta Water & Infr | S43: 22.05 | T43: 12.24 | U43: 1
R44: Mukka Proteins Ltd | S44: 22.4 | T44: 57.14 | U44: 1
R45: Tolins Tyres Ltd | S45: 23 | T45: 0.44 | U45: 1
R46: Platinum Industrie | S46: 23.532 | T46: 33.33 | U46: 1
R47: Dharmaj Crop Guard | S47: 25.109 | T47: 12.24 | U47: 1
R48: J.G.Chemicals Ltd | S48: 25.119 | T48: -4.52 | U48: 1
R49: Laxmi India Financ | S49: 25.426 | T49: -13.92 | U49: 1
R50: Radiant Cash Manag | S50: 25.664 | T50: 5.64 | U50: 1
R51: Deepak Builders & | S51: 26.004 | T51: -2.22 | U51: 1
R52: Indo Farm Equipmen | S52: 26.015 | T52: 20.19 | U52: 1
R53: Garuda Constructio | S53: 26.41 | T53: 8.63 | U53: 1
R54: Manoj Vaibhav Gems | S54: 27.02 | T54: 0 | U54: 1
R55: Unicommerce eSolut | S55: 27.657 | T55: 112.96 | U55: 1
...

Sheet DASHBOARD(ISSUE SIZE)
B2: IPO DATASET
J4: =Total_vs_Gains!J39 -> 0
V12: Row Labels | W12: Sum of Issue size divide by 10 | X12: Sum of Listing Gains(%) | Y12: Count of First name
V13: Abans Financial Se | W13: 34.56 | X13: 0 | Y13: 1
V14: Aeroflex Industrie | W14: 35.1 | X14: 82.78 | Y14: 1
V15: Akme Fintrade (Ind | W15: 13.2 | X15: 4.75 | Y15: 1
K16: postive | L16: NEGATIVE | N16: NEUTRAL | Q16: Average gains | V16: All Time Plastics | W16: 40.06 | X16: 14.29 | Y16: 1
K17: {=MAX(0, SUMPRODUCT( SUBTOTAL(103, OFFSET($X$13, ROW($X$13:$X$320)-ROW($X$13), 0, 1)) * --(ISNUMBER($X$13:$X$320)) * --($X$13:$X$320 > 0) ) ) - 1} -> 67 | L17: {=MAX(0, SUMPRODUCT( SUBTOTAL(103, OFFSET($X$13, ROW($X$13:$X$320)-ROW($X$13), 0, 1)) * --(ISNUMBER($X$13:$X$320)) * --($X$13:$X$320 < 0) ) )} -> 11 | N17: {=MAX(0, SUMPRODUCT( SUBTOTAL(103, OFFSET($X$13, ROW($X$13:$X$320)-ROW($X$13), 0, 1)) * --(ISNUMBER($X$13:$X$320)) * --($X$13:$X$320 = 0) ) )} -> 7 | Q17: =GETPIVOTDATA("Sum of Listing Gains(%)",$V$12)/GETPIVOTDATA("Count of First name",$V$12) -> 31.582706 | V17: Antony Waste Handl | W17: 29.999 | X17: 36.51 | Y17: 1
V18: Arisinfra Solution | W18: 49.96 | X18: -5.81 | Y18: 1
V19: Arkade Developers | W19: 41 | X19: 37.42 | Y19: 1
V20: Barbeque-Nation Ho | W20: 45.287 | X20: -1.6 | Y20: 1
V21: BLS E-Services Ltd | W21: 30.929 | X21: 128.89 | Y21: 1
V22: Borana Weaves Ltd | W22: 14.489 | X22: 12.5 | Y22: 1
V23: DEE Development En | W23: 41.801 | X23: 60.1 | Y23: 1
V24: Deepak Builders & | W24: 26.004 | X24: -2.22 | Y24: 1
V25: Denta Water & Infr | W25: 22.05 | X25: 12.24 | Y25: 1
V26: Dharmaj Crop Guard | W26: 25.109 | X26: 12.24 | Y26: 1
V27: Diffusion Engineer | W27: 15.796 | X27: 11.9 | Y27: 1
V28: Divgi Torqtransfer | W28: 41.212 | X28: 1.69 | Y28: 1
V29: Elin Electronics L | W29: 47.5 | X29: -1.62 | Y29: 1
... V98: Grand Total | W98: 2221.921 | X98: 2684.53 | Y98: 85

Sheet DASHBOARD(SUB)
B2: IPO DATASET
J4: =Total_vs_Gains!J39 -> 0
V11: IPO NAME | W11: Total SuCcription | X11: Sum of Listing Gains(%) | Y11: Gains(%) | Z11: Count of IPO NAME
V12: Borana Weaves Ltd | W12: 148.78 | X12: 12.5 | Y12: 12.5 | Z12: 1
V13: Exicom Tele-System | W13: 129.54 | X13: 85.92 | Y13: 85.92 | Z13: 1
V14: GNG Electronics Lt | W14: 147.93 | X14: 47.68 | Y14: 47.68 | Z14: 1
V15: Go Fashion (India) | W15: 135.46 | X15: 90.72 | Y15: 90.72 | Z15: 1
V16: Mukka Proteins Ltd | W16: 136.99 | X16: 57.14 | Y16: 57.14 | Z16: 1
V17: Rolex Rings Ltd | W17: 130.44 | X17: 38.78 | Y17: 38.78 | Z17: 1
V18: Grand Total | W18: 829.14 | X18: 332.74 | Y18: 332.74 | Z18: 6

Sheet ALL DATA 
G2: ISSUE SIZE | H2: NO COM | I2: SUM OF GAINS | J2: AVERGAE GAINS | L2: ISSUE SIZE | M2: NO COM | N2: SUM OF GAINS | O2: AVERGAE GAINS | Q2: ISSUE SIZE | R2: NO COM | S2: SUM OF GAINS | T2: AVERGAE GAINS | V2: ISSUE SIZE | W2: NO COM | X2: SUM OF GAINS | Y2: AVERGAE GAINS | AC2: ISSUE | AD2: AVERAGE GAINS | AE2: 2021 AVERAGE GAIN | AF2: 2022 | AG2: 23 | AH2: 24 | AI2: 25
A3: GRP BY 50IN 500 | B3: Grp by total | C3: Count of Listing Gains(%) | D3: Sum of Listing Gains(%) | E3: Count of IPO NAME | G3: 50-100 | H3: 5 | I3: 282.79 | J3: =I3/H3 -> 56.558 | L3: 500-550 | M3: 18 | N3: 552.54 | O3: =N3/M3 -> 30.696667 | Q3: 1000-1050 | R3: 6 | S3: 223.53 | T3: =S3/R3 -> 37.255 | V3: 1500-1550 | W3: 6 | X3: 118.71 | Y3: =X3/W3 -> 19.785 | AC3: 0-500 | AD3: 31.5 | AE3: 61.77 | AF3: 8.96 | AG3: 23.7 | AH3: 42.7 | AI3: 20.22
A4: 500-550 | B4: 0 to 5 | C4: 2 | D4: -2.29 | E4: 2 | G4: 100-150 | H4: 12 | I4: 545.54 | J4: =I4/H4 -> 45.461667 | L4: 550-600 | M4: 19 | N4: 660.1 | O4: =N4/M4 -> 34.742105 | Q4: 1050-1100 | R4: 1 | S4: -1.61 | T4: =S4/R4 -> -1.61 | V4: 1550-1600 | W4: 6 | X4: 59.77 | Y4: =X4/W4 -> 9.9616667 | AC4: 500-1000 | AD4: 24.7 | AE4: 39.5 | AF4: 15.09 | AG4: 25.1 | AH4: 22.8 | AI4: 10.6
B5: 10 to 15 | C5: 1 | D5: 18.69 | E5: 1 | G5: 150-200 | H5: 17 | I5: 672.43 | J5: =I5/H5 -> 39.554706 | L5: 600-650 | M5: 15 | N5: 521.43 | O5: =N5/M5 -> 34.762 | Q5: 1100-1150 | R5: 4 | S5: 75.09 | T5: =S5/R5 -> 18.7725 | V5: 1600-1650 | W5: 2 | X5: 10.66 | Y5: =X5/W5 -> 5.33 | AC5: 1000-1500 | AD5: 18.9 | AE5: 18.5 | AF5: 9.9 | AG5: 26.27 | AH5: 16.05 | AI5: 16
B6: 100 to 125 | C6: 1 | D6: 59.8 | E6: 1 | G6: 200-250 | H6: 8 | I6: 158.53 | J6: =I6/H6 -> 19.81625 | L6: 650-700 | M6: 7 | N6: 69.56 | O6: =N6/M6 -> 9.9371429 | Q6: 1150-1200 | R6: 4 | S6: 89.36 | T6: =S6/R6 -> 22.34 | V6: 1700-1750 | W6: 1 | X6: 0 | Y6: =X6/W6 -> 0 | AC6: 1500-2000 | AD6: 16.28 | AE6: 40.3 | AF6: -1.8 | AG6: 15.9 | AH6: 19.7 | AI6: -0.5
B7: 15 to 20 | C7: 1 | D7: 0 | E7: 1 | G7: 250-300 | H7: 11 | I7: 204.48 | J7: =I7/H7 -> 18.589091 | L7: 700-750 | M7: 8 | N7: 213.01 | O7: =N7/M7 -> 26.62625 | Q7: 1200-1250 | R7: 5 | S7: 107.56 | T7: =S7/R7 -> 21.512 | V7: 1800-1850 | W7: 3 | X7: 102.95 | Y7: =X7/W7 -> 34.316667 | AC7: 2000-2500 | AD7: 17.02 | AE7: 16.69 | AF7: 18.5 | AG7: 56.25 | AH7: 12.5 | AI7: 5.91
B8: 150 to 175 | C8: 1 | D8: 10.16 | E8: 1 | G8: 300-350 | H8: 8 | I8: 394.88 | J8: =I8/H8 -> 49.36 | L8: 750-800 | M8: 6 | N8: 66.41 | O8: =N8/M8 -> 11.068333 | Q8: 1250-1300 | R8: 4 | S8: 0.07 | T8: =S8/R8 -> 0.0175 | V8: 1850-1900 | W8: 2 | X8: 8.9 | Y8: =X8/W8 -> 4.45 | AC8: 2500-3000 | AD8: 11.124 | AE8: -4 | AF8: 0 | AG8: 20 | AH8: 37 | AI8: -2.4 | BQ8: TOATL SUB | BR8: 0-5 | BS8: 5-10 | BT8: 10-15 | BU8: 15-20 | BV8: 20-25 | BW8: 25-50 | BX8: 50-75 | BY8: 75-100 | BZ8: 100-125 | CA8: 125-150 | CB8: 150-175 | CC8: 175-200 | CD8: >200
B9: 175 to 200 | C9: 2 | D9: 184.94 | E9: 2 | G9: 350-400 | H9: 2 | I9: 97.91 | J9: =I9/H9 -> 48.955 | L9: 800-850 | M9: 14 | N9: 137.37 | O9: =N9/M9 -> 9.8121429 | Q9: 1300-1350 | R9: 2 | S9: 36.65 | T9: =S9/R9 -> 18.325 | V9: 1900-1950 | W9: 1 | X9: 28.24 | Y9: =X9/W9 -> 28.24 | AC9: 3000-3500 | AD9: 27.99 | AE9: 0 | AF9: 8.08 | AG9: 71.13 | AH9: 10 | AI9: 12.7 | BQ9: WITHOUT OULINERS | BR9: -1.0365 | BS9: 5.0388 | BT9: 9.235 | BU9: 4.13 | BV9: 6.56 | BW9: 23.046875 | BX9: 40.151 | BY9: 38.553333 | BZ9: 51.866667 | CA9: 50.81 | CB9: 77.68 | CC9: 73.355 | CD9: 92.768 | DJ9: AVERGAE LISTING AGINS
B10: 25 to 50 | C10: 3 | D10: 52.48 | E10: 3 | G10: 400-450 | H10: 13 | I10: 261.21 | J10: =I10/H10 -> 20.093077 | L10: 850-900 | M10: 8 | N10: 112.21 | O10: =N10/M10 -> 14.02625 | Q10: 1350-1400 | R10: 5 | S10: 42.83 | T10: =S10/R10 -> 8.566 | V10: 1950-2000 | W10: 2 | X10: 45.36 | Y10: =X10/W10 -> 22.68 | AC10: 3500-4000 | AD10: -1.8 | AE10: -1.42 | AF10: -3.41 | AG10: 0 | AH10: 0 | AI10: -1.7 | BQ10: WITH OUTLINERS | BR10: 1.855 | BS10: 4.6855 | BT10: 13.348333 | BU10: 7.3825 | BV10: 10.67 | BW10: 22.727222 | BX10: 59.325625 | BY10: 52.198333 | BZ10: 51.866667 | CA10: 60.103333 | CB10: 46.963333 | CC10: 73.355 | CD10: 92.768 | DH10: AVERGAE LISTING GAINS | DI10: 2021 | DJ10: 2022 | DK10: 2023 | DL10: 2024 | DM10: 2025
B11: 5 to 10 | C11: 2 | D11: 51.44 | E11: 2 | G11: 450-500 | H11: 9 | I11: 66.76 | J11: =I11/H11 -> 7.4177778 | L11: 900-950 | M11: 2 | N11: 40.58 | O11: =N11/M11 -> 20.29 | Q11: 1450-1500 | R11: 2 | S11: 51.71 | T11: =S11/R11 -> 25.855 | AC11: 4000-4500 | AD11: 31.25 | AE11: 0 | AF11: 30.7 | AG11: 20 | AH11: 39.4 | AI11: 10 | BQ11: DIFFERENCE | BR11: =BR9-BR10 -> -2.8915 | BS11: =BS9-BS10 -> 0.3533 | BT11: =BT9-BT10 -> -4.1133333 | BU11: =BU9-BU10 -> -3.2525 | BV11: =BV9-BV10 -> -4.11 | BW11: =BW9-BW10 -> 0.31965278 | BX11: =BX9-BX10 -> -19.174625 | BY11: =BY9-BY10 -> -13.645 | ... CD11: =CD9-CD10 -> 0 | DG11: 0-5 | DH11: -0.2 | DI11: -3.8 | DJ11: 4.66 | DK11: 1 | DL11: -1.6 | DM11: -2.7
B12: 50 to 75 | C12: 4 | D12: 165.32 | E12: 4 | L12: 950-1000 | M12: 3 | N12: 98.92 | O12: =N12/M12 -> 32.973333 | AC12: 4500-5000 | AD12: -5.74 | AE12: -10.61 | AF12: 0 | AG12: 0 | AH12: 0 | AI12: 4 | DG12: 5-10 | DH12: 5.3 | DI12: 5.7 | DJ12: 3.7 | DK12: 2.33 | DL12: 9.06 | DM12: 4.2
B13: 75 to 100 | C13: 1 | D13: 12 | E13: 1 | AC13: >5000 | AD13: 16.48 | AE13: 19.95 | AF13: -3.6 | AG13: 0 | AH13: 20.5 | AI13: 8 | CI13: Issue Size | CJ13: With outliners | CK13: Without outliners | DG13: 10-15 | DH13: 9.77 | DI13: 0 | DK13: 6.5 | DL13: 17.5 | DM13: 1.14
A14: 500-550 Total | C14: 18 | D14: 552.54 | E14: 18 | CI14: 0-500 | CJ14: 32.613 | CK14: 32.613 | CL14: DIFFERENCE | DG14: 15-20 | DH14: 10.1 | DI14: 10.8 | DJ14: 7.5 | DK14: 15 | DL14: 1.18 | DM14: 12.84
A15: 550-600 | B15: > 200 | C15: 1 | D15: 85.03 | E15: 1 | CI15: 500-1000 | CJ15: 32.289692 | CK15: 34.7826 | CL15: =CK15-CJ15 -> 2.4929077 | DG15: 20-25 | DH15: 8.2 | DI15: 3.9 | DK15: 10.7 | DL15: 6.8 | DM15: 23
B16: 0 to 5 | C16: 3 | D16: -22.57 | E16: 3 | Q16: TOTAL SUB | AE16: POSTIVE | AF16: NEGATIVE | AG16: NO GAINS | CI16: 1000-1500 | CJ16: 29.25 | CK16: 20.82 | CL16: =CK16-CJ16 -> -8.43 | DF16: TOTAL SUB | DG16: 25-50 | DH16: 18.95 | DI16: 31.4 | DJ16: 16.77 | DK16: 21.1 | DL16: 13.86 | DM16: 9.4
B17: 10 to 15 | C17: 2 | D17: 5.93 | E17: 2 | L17: 0-5 | M17: 5-10 | N17: 10-15 | O17: 15-20 | P17: 20-25 | Q17: 25-50 | R17: 50-75 | S17: 75-100 | T17: 100-125 | U17: 125-150 | V17: 150-175 | W17: 175-200 | X17: >200 | AE17: 67 | AF17: 11 | AG17: 7 | CI17: 1500-2000 | CJ17: 22.061429 | CK17: 22.23 | CL17: =CK17-CJ17 -> 0.16857143 | DG17: 50-75 | DH17: 40.32 | DI17: 48.3 | DJ17: 48.2 | DK17: 40.46 | DL17: 43.3 | DM17: 15.13
B18: 100 to 125 | C18: 4 | D18: 213.27 | E18: 4 | K18: 0-500 | L18: 5.5 | M18: 5.154 | N18: 13.81 | O18: 18.42 | P18: 3.45 | Q18: 6.98 | R18: 15.135 | S18: 37.93 | T18: 51.6 | U18: 50.81 | V18: 77.68 | W18: 58.73 | X18: 78.77 | Z18: =AVERAGE(L18:X18) -> 32.613 | AE18: 74 | AF18: 23 | AG18: 3 | CI18: 2000-2500 | CJ18: 18.032 | CK18: 12.6275 | CL18: =CK18-CJ18 -> -5.4045 | DG18: 75-100 | DH18: 43.25 | DI18: 42.3 | DK18: 56.76 | DL18: 41.19 | DM18: 20.83
B19: 15 to 20 | C19: 1 | D19: -4.35 | E19: 1 | K19: 500-1000 | L19: -3 | M19: 8.79 | N19: 4.66 | O19: 3.14 | P19: 23 | Q19: 18.87 | R19: 35.37 | S19: 44.15 | T19: 41.1 | U19: 38.78 | V19: 10.16 | W19: 87.98 | X19: 106.766 | Z19: =AVERAGE(L19:X19) -> 32.289692 | AE19: 25 | AF19: 8 | AG19: 6 | CI19: 2500-3000 | CJ19: 25.814 | CK19: -6.35 | CL19: =CK19-CJ19 -> -32.164 | DG19: 100-125 | DH19: 48.26 | DI19: 78.7 | DK19: 77 | DL19: 26.49 | DM19: 37.085
B20: 175 to 200 | C20: 1 | D20: 79.02 | E20: 1 | K20: 1000-1500 | L20: -2 | M20: -1 | N20: 2.99 | O20: -1.46 | Q20: 14.94 | R20: 38.78 | S20: 33.58 | T20: 62.9 | U20: 90.72 | V20: 53.05 | Z20: =AVERAGE(L20:X20) -> 29.25 | AE20: 17 | AF20: 4 | AG20: 2 | CI20: 3000-3500 | CJ20: 17.43 | CK20: 16.872 | CL20: =CK20-CJ20 -> -0.558 | DG20: 125-150 | DH20: 55.4 | DI20: 64.9 | DL20: 71.53 | DM20: 30.09
B21: 25 to 50 | C21: 2 | D21: 96.02 | E21: 2 | K21: 1500-2000 | L21: -0.07 | M21: 1.6 | O21: 13.91 | P21: 17.33 | Q21: 43.61 | R21: 28.05 | S21: 50 | Z21: =AVERAGE(L21:X21) -> 22.061429 | AE21: 10 | AF21: 0 | AG21: 0 | CI21: 3500-4000 | CJ21: -4.7 | CK21: -4.7 | CL21: =CK21-CJ21 -> 0 | DG21: 150-175 | DH21: 66.16 | DI21: 31.6 | DK21: 72.23 | DL21: 94.21
B22: 50 to 75 | C22: 4 | D22: 155.91 | E22: 4 | J22: ISSUE SIZE | K22: 2000-2500 | L22: 8.57 | M22: 10.2 | P22: -1.1 | Q22: 32.84 | R22: 39.65 | Z22: =AVERAGE(L22:X22) -> 18.032 | AE22: 4 | AF22: 5 | AG22: 1 | CI22: 4000-4500 | CJ22: 26.6825 | CK22: 21.18 | CL22: =CK22-CJ22 -> -5.5025 | DG22: 175-200 | DH22: 71.26 | DI22: 87.01 | DL22: 118 | DM22: 29.33
B23: 75 to 100 | C23: 1 | D23: 51.84 | E23: 1 | K23: 2500-3000 | L23: -6.2 | M23: 1.6 | O23: -6.5 | Q23: 20.17 | R23: 120 | Z23: =AVERAGE(L23:X23) -> 25.814 | AE23: 5 | AF23: 2 | AG23: 0 | CI23: 4500-5000 | CJ23: 21.02 | CK23: -10.6 | CL23: =CK23-CJ23 -> -31.62 | DG23: >200 | DH23: 86.4 | DI23: 122.9 | DL23: 89.8 | DM23: 33.19
A24: 550-600 Total | C24: 19 | D24: 660.1 | E24: 19 | K24: 3000-3500 | L24: 3.02 | M24: 2.05 | N24: 20.22 | O24: -3.91 | Q24: -0.22 | R24: 83.42 | Z24: =AVERAGE(L24:X24) -> 17.43 | AE24: 1 | AF24: 4 | AG24: 0 | BL24: =AVERAGE(Z48:Z58) -> 14.509252 | CI24: >5000 | CJ24: 43.59 | CK24: 20.126667 | CL24: =CK24-CJ24 -> -23.463333
A25: 600-650 | B25: > 200 | C25: 2 | D25: 235.27 | E25: 2 | K25: 3500-4000 | L25: -4.7 | Z25: =AVERAGE(L25:X25) -> -4.7 | AE25: 7 | AF25: 0 | AG25: 0
B26: 0 to 5 | C26: 4 | D26: -18.8 | E26: 4 | K26: 4000-4500 | L26: 30.77 | N26: 34.41 | O26: 20.37 | Q26: 21.18 | Z26: =AVERAGE(L26:X26) -> 26.6825 | AE26: 0 | AF26: 3 | AG26: 0 | CI26: AVE | CJ26: =AVERAGE(CJ14:CJ24) -> 24.007511 | CK26: =AVERAGE(CK14:CK24) -> 14.509252
B27: 100 to 125 | C27: 1 | D27: 20.15 | E27: 1 | K27: 4500-5000 | L27: -10.6 | N27: 4 | S27: 69.66 | Z27: =AVERAGE(L27:X27) -> 21.02 | AE27: 13 | AF27: 6 | AG27: 0 | CI27: SD | CJ27: =_xlfn.STDEV.P(CJ15:CJ24) -> 11.825268 | CK27: =_xlfn.STDEV.P(CK15:CK24) -> 14.133031 | DJ27: POSTIVE GAINS | DK27: NEGATIVE GAINS | DL27: NEUTRAL GAINS
B28: 15 to 20 | C28: 1 | D28: -2.17 | E28: 1 | K28: >5000 | L28: -0.885 | M28: 9.09 | O28: 15.09 | Q28: 46.175 | R28: 114.2 | S28: 77.87 | Z28: =AVERAGE(L28:X28) -> 43.59 | DJ28: 5 | DK28: 14 | DL28: 0
B29: 25 to 50 | C29: 1 | D29: 49.4 | E29: 1 | BQ29: QIB GRP | BR29: NO COM | BS29: SUM GAINS | BT29: AVERAGE GAINS | DJ29: 18 | DK29: 4 | DL29: 2
B30: 50 to 75 | C30: 3 | D30: 62.07 | E30: 3 | L30: =AVERAGE(L18:L28) -> 1.855 | M30: =AVERAGE(M18:M28) -> 4.6855 | N30: =AVERAGE(N18:N28) -> 13.348333 | O30: =AVERAGE(O18:O28) -> 7.3825 | P30: =AVERAGE(P18:P28) -> 10.67 | Q30: =AVERAGE(Q18:Q28) -> 22.727222 | R30: =AVERAGE(R18:R28) -> 59.325625 | S30: =AVERAGE(S18:S28) -> 52.198333 | ... X30: =AVERAGE(X18:X28) -> 92.768 | BQ30: 0-5 | BR30: 73 | BS30: 174.04 | BT30: =BS30/BR30 -> 2.3841096 | DJ30: 9 | DK30: 3 | DL30: 0
B31: 75 to 100 | C31: 3 | D31: 175.51 | E31: 3 | BQ31: 5-15 | BR31: 41 | BS31: 126.98 | BT31: =BS31/BR31 -> 3.0970732 | DJ31: 11 | DK31: 6 | DL31: 0
A32: 600-650 Total | C32: 15 | D32: 521.43 | E32: 15 | Z32: =AVERAGE(Z18:Z28) -> 24.007511 | AX32: YEAR | AY32: postive | AZ32: negative | BA32: neutral | BB32: avergae gain | BC32: total | BD32: %postive | BE32: %negative | BF32: neutral | BQ32: 15-30 | BR32: 22 | BS32: 117.35 | BT32: =BS32/BR32 -> 5.3340909 | DJ32: 6 | DK32: 2 | DL32: 1
A33: 650-700 | B33: 100 to 125 | C33: 1 | D33: 23.36 | E33: 1 | AM33: YEAR | AN33: AVERAGE GAIN | AO33: MARKET GAIN | AX33: 2021 | AY33: 46 | AZ33: 19 | BA33: 0 | BB33: 30.28 | BC33: =AY33+AZ33+BA33 -> 65 | BD33: =AY33/BC33 *100 -> 70.769231 | BE33: =AZ33/BC33 *100 -> 29.230769 | BF33: =BA33/BC33 -> 0 | BQ33: 30-60 | BR33: 31 | BS33: 396.1 | BT33: =BS33/BR33 -> 12.777419 | DJ33: 33 | DK33: 8 | DL33: 3
B34: 25 to 50 | C34: 2 | D34: 1.59 | E34: 2 | AM34: 2021 | AN34: 30.28 | AO34: 22 | AX34: 2022 | AY34: 27 | AZ34: 10 | BA34: 2 | BB34: 10.2 | BC34: =AY34+AZ34+BA34 -> 39 | BD34: =AY34/BC34 *100 -> 69.230769 | BE34: =AZ34/BC34 *100 -> 25.641026 | BF34: =BA34/BC34 *100 -> 5.1282051 | BQ34: 60-90 | BR34: 33 | BS34: 1093.74 | BT34: =BS34/BR34 -> 33.143636 | DJ34: 35 | DK34: 0 | DL34: 1
B35: 5 to 10 | C35: 3 | D35: -2.69 | E35: 3 | AM35: 2022 | AN35: 10.2 | AO35: 4.5 | AX35: 2023 | AY35: 47 | AZ35: 8 | BA35: 5 | BB35: 26.06 | BC35: =AY35+AZ35+BA35 -> 60 | BD35: =AY35/BC35 *100 -> 78.333333 | BE35: =AZ35/BC35 *100 -> 13.333333 | BF35: =BA35/BC35 *100 -> 8.3333333 | BQ35: 90-120 | BR35: 26 | BS35: 942.9 | BT35: =BS35/BR35 -> 36.265385 | DJ35: 25 | DK35: 0 | DL35: 0
B36: 75 to 100 | C36: 1 | D36: 47.3 | E36: 1 | AM36: 2023 | AN36: 26.06 | AO36: 18.8 | AX36: 2024 | AY36: 72 | AZ36: 18 | BA36: 2 | BB36: 28.49 | BC36: =AY36+AZ36+BA36 -> 92 | BD36: =AY36/BC36 *100 -> 78.26087 | BE36: =AZ36/BC36 *100 -> 19.565217 | BF36: =BA36/BC36 *100 -> 2.173913 | BQ36: 120-160 | BR36: 27 | BS36: 1384.71 | BT36: =BS36/BR36 -> 51.285556 | DJ36: 20 | DK36: 0 | DL36: 0
A37: 650-700 Total | C37: 7 | D37: 69.56 | E37: 7 | AM37: 2024 | AN37: 28.49 | AO37: 8.12 | AX37: 2025 | AY37: 32 | AZ37: 9 | BA37: 3 | BB37: 12.34 | BC37: =AY37+AZ37+BA37 -> 44 | BD37: =AY37/BC37 *100 -> 72.727273 | BE37: =AZ37/BC37 *100 -> 20.454545 | BF37: =BA37/BC37 *100 -> 6.8181818 | BQ37: 160-200 | BR37: 29 | BS37: 1549.02 | BT37: =BS37/BR37 -> 53.414483 | DJ37: 6 | DK37: 0 | DL37: 0
A38: 700-750 | B38: 0 to 5 | C38: 1 | D38: -6.92 | E38: 1 | AM38: 2025 | AN38: 12.34 | AO38: 2 | BA38: SD | BB38: =_xlfn.STDEV.P(BB33:BB37) -> 8.4656284 | BC38: average | BD38: =AVERAGE(BD33:BD37) -> 73.864295 | BE38: =AVERAGE(BE33:BE37) -> 21.644978 | BF38: =AVERAGE(BF33:BF37) -> 4.4907267 | BQ38: 200-250 | BR38: 15 | BS38: 1010.28 | BT38: =BS38/BR38 -> 67.352 | DJ38: 8 | DK38: 0 | DL38: 0
B39: 10 to 15 | C39: 2 | D39: 7.86 | E39: 2 | BQ39: 250-300 | BR39: 2 | BS39: 161.32 | BT39: =BS39/BR39 -> 80.66 | DJ39: 7 | DK39: 0 | DL39: 0
B40: 125 to 150 | C40: 1 | D40: 38.78 | E40: 1 | BQ40: >300 | BR40: 3 | BS40: 182.79 | BT40: =BS40/BR40 -> 60.93 | DJ40: 11 | DK40: 0 | DL40: 0
B41: 50 to 75 | C41: 2 | D41: 92.63 | E41: 2
...

Sheet subvsgains
C1: total sub | D1: LISTIING GAINS | F1: POSTIVE GAINS | G1: NEGATIVE GAINS | H1: NEUTRAL GAINS | J1: 2021 average gains | K1: 2022 | L1: 2023 | M1: 2024 | N1: 2025
C2: 0-5 | D2: -0.2 | F2: 5 | G2: 14 | H2: 0 | J2: -3.8 | K2: 4.66 | L2: 1 | M2: -1.6 | N2: -2.7
C3: 5-10 | D3: 5.3 | F3: 18 | G3: 4 | H3: 2 | J3: 5.7 | K3: 3.7 | L3: 2.33 | M3: 9.06 | N3: 4.2
C4: 10-15 | D4: 9.77 | F4: 9 | G4: 3 | H4: 0 | J4: 0 | L4: 6.5 | M4: 17.5 | N4: 1.14
C5: 15-20 | D5: 10.1 | F5: 11 | G5: 6 | H5: 0 | J5: 10.8 | K5: 7.5 | L5: 15 | M5: 1.18 | N5: 12.84
C6: 20-25 | D6: 8.2 | F6: 6 | G6: 2 | H6: 1 | J6: 3.9 | L6: 10.7 | M6: 6.8 | N6: 23
C7: 25-50 | D7: 18.95 | F7: 33 | G7: 8 | H7: 3 | J7: 31.4 | K7: 16.77 | L7: 21.1 | M7: 13.86 | N7: 9.4
C8: 50-75 | D8: 40.32 | F8: 35 | G8: 0 | H8: 1 | J8: 48.3 | K8: 48.2 | L8: 40.46 | M8: 43.3 | N8: 15.13
C9: 75-100 | D9: 43.25 | F9: 25 | G9: 0 | H9: 0 | J9: 42.3 | L9: 56.76 | M9: 41.19 | N9: 20.83
C10: 100-125 | D10: 48.26 | F10: 20 | G10: 0 | H10: 0 | J10: 78.7 | L10: 77 | M10: 26.49 | N10: 37.085
C11: 125-150 | D11: 55.4 | F11: 6 | G11: 0 | H11: 0 | J11: 64.9 | M11: 71.53 | N11: 30.09
C12: 150-175 | D12: 66.16 | F12: 8 | G12: 0 | H12: 0 | J12: 31.6 | L12: 72.23 | M12: 94.21
C13: 175-200 | D13: 71.26 | F13: 7 | G13: 0 | H13: 0 | J13: 87.01 | M13: 118 | N13: 29.33
C14: >200 | D14: 86.4 | F14: 11 | G14: 0 | H14: 0 | J14: 122.9 | M14: 89.8 | N14: 33.19

Sheet issuevsgains 
B1: ISSUE | C1: AVERAGE GAINS | D1: POSTIVE | E1: NEGATIVE | F1: NO GAINS | G1: 2021 AVERAGE GAIN | H1: 2022 | I1: 23 | J1: 24 | K1: 25
B2: 0-500 | C2: 31.5 | D2: 67 | E2: 11 | F2: 7 | G2: 61.77 | H2: 8.96 | I2: 23.7 | J2: 42.7 | K2: 20.22 | M2: =_xlfn.STDEV.S(G2:K2) -> 20.843694
B3: 500-1000 | C3: 24.7 | D3: 74 | E3: 23 | F3: 3 | G3: 39.5 | H3: 15.09 | I3: 25.1 | J3: 22.8 | K3: 10.6 | M3: =_xlfn.STDEV.S(G3:K3) -> 11.0939
B4: 1000-1500 | C4: 18.9 | D4: 25 | E4: 8 | F4: 6 | G4: 18.5 | H4: 9.9 | I4: 26.27 | J4: 16.05 | K4: 16 | M4: =_xlfn.STDEV.S(G4:K4) -> 5.9140451
B5: 1500-2000 | C5: 16.28 | D5: 17 | E5: 4 | F5: 2 | G5: 40.3 | H5: -1.8 | I5: 15.9 | J5: 19.7 | K5: -0.5 | M5: =_xlfn.STDEV.S(G5:K5) -> 17.212554
B6: 2000-2500 | C6: 17.02 | D6: 10 | E6: 0 | F6: 0 | G6: 16.69 | H6: 18.5 | I6: 56.25 | J6: 12.5 | K6: 5.91 | M6: =_xlfn.STDEV.S(G6:K6) -> 19.765135
B7: 2500-3000 | C7: 11.124 | D7: 4 | E7: 5 | F7: 1 | G7: -4 | H7: 0 | I7: 20 | J7: 37 | K7: -2.4 | M7: =_xlfn.STDEV.S(G7:K7) -> 17.879374
B8: 3000-3500 | C8: 27.99 | D8: 5 | E8: 2 | F8: 0 | G8: 0 | H8: 8.08 | I8: 71.13 | J8: 10 | K8: 12.7 | M8: =_xlfn.STDEV.S(G8:K8) -> 28.761622
B9: 3500-4000 | C9: -1.8 | D9: 1 | E9: 4 | F9: 0 | G9: -1.42 | H9: -3.41 | I9: 0 | J9: 0 | K9: -1.7 | M9: =_xlfn.STDEV.S(G9:K9) -> 1.4147721
B10: 4000-4500 | C10: 31.25 | D10: 7 | E10: 0 | F10: 0 | G10: 0 | H10: 30.7 | I10: 20 | J10: 39.4 | K10: 10 | M10: =_xlfn.STDEV.S(G10:K10) -> 15.738869
B11: 4500-5000 | C11: -5.74 | D11: 0 | E11: 3 | F11: 0 | G11: -10.61 | H11: 0 | I11: 0 | J11: 0 | K11: 4 | M11: =_xlfn.STDEV.S(G11:K11) -> 5.4734285
B12: >5000 | C12: 16.48 | D12: 13 | E12: 6 | F12: 0 | G12: 19.95 | H12: -3.6 | I12: 0 | J12: 20.5 | K12: 8 | M12: =_xlfn.STDEV.S(G12:K12) -> 11.100766
G15: =_xlfn.STDEV.S(G2:G12) -> 22.76295 | H15: =_xlfn.STDEV.S(H2:H12) -> 10.799554 | I15: =_xlfn.STDEV.S(I2:I12) -> 22.562048 | J15: =_xlfn.STDEV.S(J2:J12) -> 14.69913 | K15: =_xlfn.STDEV.S(K2:K12) -> 7.3390503

Sheet FOR NO OF +
A3: Row Labels | B3: Gains(%) | C3: Count of IPO NAME | F3: No of companies | G3: =_xlfn.XLOOKUP(A14,A14,GETPIVOTDATA("Count of IPO NAME",$A$3)) -> 7 | H3: Percentage in positive | I3: {=SUMPRODUCT( SUBTOTAL(103, OFFSET($B$4, ROW($B$4:$B$303)-ROW($B$4), 0, 1)) * --(ISNUMBER($B$4:$B$303)) * --($B$4:$B$303 >= 0) )} -> 8 | J3: COMPANIES IN NEGATIVE
A4: Protean eGov Techn | B4: 0 | C4: 1
A5: Abans Financial Se | B5: 0 | C5: 1 | I5: =COUNT(A4:A37) -> 0
A6: RBZ Jewellers Ltd | B6: 0 | C6: 1
A7: Manoj Vaibhav Gems | B7: 0 | C7: 1
A8: Scoda Tubes Ltd | B8: 0 | C8: 1
A9: Indogulf Cropscien | B9: 0 | C9: 1
A10: Udayshivakumar Inf | B10: 0 | C10: 1
A11: Grand Total | B11: 0 | C11: 7

Sheet Sheet9 (2)
A3: Row Labels | B3: Count of IPO NAME | C3: Sum of Listing Gains(%) | D3: YEAR
A4: Abans Financial Se | B4: 1 | C4: 0 | D4: =_xlfn.XLOOKUP(A4,'ipo_21-25'!C:C,'ipo_21-25'!#REF!) -> #REF! | G4: =_xlfn.XLOOKUP('FOR NO OF +'!A11,'FOR NO OF +'!A11,GETPIVOTDATA("Count of IPO NAME",'FOR NO OF +'!$A$3)) -> 7
A5: Indogulf Cropscien | B5: 1 | C5: 0 | D5: =_xlfn.XLOOKUP(A5,'ipo_21-25'!C:C,'ipo_21-25'!#REF!) -> #REF!
A6: Manoj Vaibhav Gems | B6: 1 | C6: 0 | D6: =_xlfn.XLOOKUP(A6,'ipo_21-25'!C:C,'ipo_21-25'!#REF!) -> #REF! | F6: POSITIVE GAINS | G6: NEGATIVE GAINS | H6: NO GAINS
A7: Protean eGov Techn | B7: 1 | C7: 0 | D7: =_xlfn.XLOOKUP(A7,'ipo_21-25'!C:C,'ipo_21-25'!#REF!) -> #REF! | G7: {=MAX(0, SUMPRODUCT( SUBTOTAL(103,OFFSET($B$4,ROW($B$4:$B$306)-ROW($B$4),0,1))* --(ISNUMBER($B$4:$B$306))* --($B$4:$B$306<0) ))} -> 0
A8: RBZ Jewellers Ltd | B8: 1 | C8: 0 | D8: =_xlfn.XLOOKUP(A8,'ipo_21-25'!C:C,'ipo_21-25'!#REF!) -> #REF!
A9: Scoda Tubes Ltd | B9: 1 | C9: 0 | D9: =_xlfn.XLOOKUP(A9,'ipo_21-25'!C:C,'ipo_21-25'!#REF!) -> #REF!
A10: Udayshivakumar Inf | B10: 1 | C10: 0 | D10: =_xlfn.XLOOKUP(A10,'ipo_21-25'!C:C,'ipo_21-25'!#REF!) -> #REF!
D11: =_xlfn.XLOOKUP(A11,'ipo_21-25'!C:C,'ipo_21-25'!#REF!) -> #REF!
D12: =_xlfn.XLOOKUP(A12,'ipo_21-25'!C:C,'ipo_21-25'!#REF!) -> #REF!
D13: =_xlfn.XLOOKUP(A13,'ipo_21-25'!C:C,'ipo_21-25'!#REF!) -> #REF!
D14: =_xlfn.XLOOKUP(A14,'ipo_21-25'!C:C,'ipo_21-25'!#REF!) -> #REF!
D15: =_xlfn.XLOOKUP(A15,'ipo_21-25'!C:C,'ipo_21-25'!#REF!) -> #REF!
D16: =_xlfn.XLOOKUP(A16,'ipo_21-25'!C:C,'ipo_21-25'!#REF!) -> #REF!
D17: =_xlfn.XLOOKUP(A17,'ipo_21-25'!C:C,'ipo_21-25'!#REF!) -> #REF!
D18: =_xlfn.XLOOKUP(A18,'ipo_21-25'!C:C,'ipo_21-25'!#REF!) -> #REF!
D19: =_xlfn.XLOOKUP(A19,'ipo_21-25'!C:C,'ipo_21-25'!#REF!) -> #REF!
D20: =_xlfn.XLOOKUP(A20,'ipo_21-25'!C:C,'ipo_21-25'!#REF!) -> #REF!
D21: =_xlfn.XLOOKUP(A21,'ipo_21-25'!C:C,'ipo_21-25'!#REF!) -> #REF!
D22: =_xlfn.XLOOKUP(A22,'ipo_21-25'!C:C,'ipo_21-25'!#REF!) -> #REF!
... D305: =_xlfn.XLOOKUP(A305,'ipo_21-25'!C:C,'ipo_21-25'!#REF!) -> #REF!

Sheet Sheet9
A3: Row Labels | B3: Gains(%) | C3: Count of IPO NAME | F3: No of companies | G3: =_xlfn.XLOOKUP(A14,A14,GETPIVOTDATA("Count of IPO NAME",$A$3)) -> 10
A4: Indus Infra Trust | B4: 1 | C4: 1
A5: Travel Food Servic | B5: 2.38 | C5: 1 | I5: =COUNT(A4:A37) -> 0
A6: Sagility India Ltd | B6: 3.53 | C6: 1
A7: Niva Bupa Health I | B7: 6.08 | C7: 1
A8: Belrise Industries | B8: 9.44 | C8: 1
A9: Sapphire Foods Ind | B9: 11.1 | C9: 1
A10: Global Health Ltd | B10: 18.5 | C10: 1
A11: Krishna Institute | B11: 22.29 | C11: 1
A12: Inventurus Knowled | B12: 39.65 | C12: 1
A13: Indian Renewable E | B13: 56.25 | C13: 1
A14: Grand Total | B14: 170.22 | C14: 10

Sheet ipo_21-25
A1: List Date | B1: Year | C1: IPO NAME | D1: First name | E1: name without l | F1: CMP FROM D | G1: CMP(26_09) from c | H1: Issue Size(â‚¹.Cr) | I1: GRP BY 50 | J1: GRP BY 50IN 500 | K1: Issue size divide by 10 | L1: FROM 1000-1500 | M1: FROM 1500-2000 | N1: Size grp | O1: QIB | P1: NII | Q1: RII | R1: Total | S1: Grp by total | T1: Offer Price(â‚¹) | U1: List Price | V1: Listing Gains(%) | W1: grp by Listing | X1: CMP (BSE) | Y1: CMP (NSE) | Z1: Postive | AA1: GRP BY QIB | AB1: Current Gains(%)
A2: 45889 | B2: =TEXT(A2,"yyyy") -> 2025 | C2: Regaal Resources L | D2: RegAAl Resources L | E2: RegAAl Resources L | F2: =_xlfn.XLOOKUP(E2,MARKET_PRICE__2[Column2],MARKET_PRICE__2[Column3],"Not found") -> Not found | G2: =_xlfn.XLOOKUP(D2,MARKET_PRICE__2[Column12],MARKET_PRICE__2[Column3],"Not found") -> Not found | H2: 306 | I2: {=_xlfn.IFS( H2<50,"0-50", H2<100,"50-100", H2<150,"100-150", H2<200,"150-200", H2<250,"200-250", H2<300,"250-300", H2<350,"300-350", H2<400,"350-400", H2<450,"400-450", H2<=500,"450-500", TRUE,"Above 500" )} -> 300-350 | K2: =H2/10 -> 30.6 | N2: {=_xlfn.IFS(H2<500,"0-500",H2<1000,"500-1000",H2<1500,"1000-1500",H2<2000,"1500-2000",H2<2500,"2000-2500",H2<3000,"2500-3000",H2<3500,"3000-3500",H2<4000,"3500-4000",H2<4500,"4000-4500",H2<=5000,"4500-5000",TRUE,"Hbove 5000")} -> 0-500 | O2: 190.97 | P2: 356.73 | Q2: 57.75 | R2: 159.88 | S2: {=_xlfn.IFS( R2<0,"< 0", R2<5,"0 to 5", R2<10,"5 to 10", R2<15,"10 to 15", R2<20,"15 to 20", R2<25,"20 to 25", R2<50,"25 to 50", R2<75,"50 to 75", R2<100,"75 to 100", R2<125,"100 to 125", R2<150,"125 to 150", R2<175,"150 to 175", R2<200,"175 to 200", TRUE,"> 200" )} -> 150 to 175 | T2: 102 | U2: 141.8 | V2: 39.02 | W2: {=_xlfn.IFS( V2<-15,"< -15%", V2<-10,"-15% to -10%", V2<-5,"-10% to -5%", V2<0,"-5% to 0%", V2<10,"0% to 10%", V2<20,"10% to 20%", V2<30,"20% to 30%", V2<40,"30% to 40%", V2<50,"40% to 50%", V2<60,"50% to 60%", V2<70,"60% to 70%", V2<80,"70% to 80%", V2<90,"80% to 90%", V2<100,"90% to 100%", TRUE,"> 100%" )} -> 30% to 40% | X2: 124.15 | Y2: 124.08 | Z2: =IF(V2>0, ">0", IF(V2<0, "<0", "=0")) -> >0 | AA2: {=_xlfn.IFS( AND(O2>=0,O2<5),"0-5", AND(O2>=5,O2<15),"5-15", AND(O2>=15,O2<30),"15-30", AND(O2>=30,O2<60),"30-60", AND(O2>=60,O2<90),"60-90", AND(O2>=90,O2<120),"90-120", AND(O2>=120,O2<160),"120-160", AND(O2>=160,O2<200),"160-200", AND(O2>=200,O2<250),"200-250", AND(O2>=250,O2<300),"250-300", O2>=300,">300", TRUE,"Below 0" )} -> 160-200 | AB2: 21.72
A3: 45888 | B3: =TEXT(A3,"yyyy") -> 2025 | C3: Bluestone Jeweller | D3: =IFERROR(LEFT(C3,FIND(" ",C3)-1),C3) -> Bluestone | E3: =TRIM(SUBSTITUTE(SUBSTITUTE(C3,"Ltd",""),"Lt","")) -> Bluestone Jeweller | F3: =_xlfn.XLOOKUP(E3,MARKET_PRICE__2[Column2],MARKET_PRICE__2[Column3],"Not found") -> Not found | G3: =_xlfn.XLOOKUP(D3,MARKET_PRICE__2[Column12],MARKET_PRICE__2[Column3],"Not found") -> 758.00 | H3: 1540.65 | K3: =H3/10 -> 154.065 | M3: {=_xlfn.IFS( AND(H3>=1000,H3<1050),"1000-1050", AND(H3>=1050,H3<1100),"1050-1100", AND(H3>=1100,H3<1150),"1100-1150", AND(H3>=1150,H3<1200),"1150-1200", AND(H3>=1200,H3<1250),"1200-1250", AND(H3>=1250,H3<1300),"1250-1300", AND(H3>=1300,H3<1350),"1300-1350", AND(H3>=1350,H3<1400),"1350-1400", AND(H3>=1400,H3<1450),"1400-1450", AND(H3>=1450,H3<1500),"1450-1500", AND(H3>=1500,H3<1550),"1500-1550", AND(H3>=1550,H3<1600),"1550-1600", AND(H3>=1600,H3<1650),"1600-1650", AND(H3>=1650,H3<1700),"1650-1700", AND(H3>=1700,H3<1750),"1700-1750", AND(H3>=1750,H3<1800),"1750-1800", AND(H3>=1800,H3<1850),"1800-1850", AND(H3>=1850,H3<1900),"1850-1900", AND(H3>=1900,H3<1950),"1900-1950", AND(H3>=1950,H3<=2000),"1950-2000", H3<1000,"Below 1000", TRUE,"Above 2000" )} -> 1500-1550 | N3: {=_xlfn.IFS(H3<500,"0-500",H3<1000,"500-1000",H3<1500,"1000-1500",H3<2000,"1500-2000",H3<2500,"2000-2500",H3<3000,"2500-3000",H3<3500,"3000-3500",H3<4000,"3500-4000",H3<4500,"4000-4500",H3<=5000,"4500-5000",TRUE,"Hbove 5000")} -> 1500-2000 | O3: 4.28 | P3: 0.55 | Q3: 1.35 | R3: 2.7 | S3: {=_xlfn.IFS( R3<0,"< 0", R3<5,"0 to 5", R3<10,"5 to 10", R3<15,"10 to 15", R3<20,"15 to 20", R3<25,"20 to 25", R3<50,"25 to 50", R3<75,"50 to 75", R3<100,"75 to 100", R3<125,"100 to 125", R3<150,"125 to 150", R3<175,"150 to 175", R3<200,"175 to 200", TRUE,"> 200" )} -> 0 to 5 | T3: 517 | U3: 508.8 | V3: -1.59 | W3: {=_xlfn.IFS( V3<-15,"< -15%", V3<-10,"-15% to -10%", V3<-5,"-10% to -5%", V3<0,"-5% to 0%", V3<10,"0% to 10%", V3<20,"10% to 20%", V3<30,"20% to 30%", V3<40,"30% to 40%", V3<50,"40% to 50%", V3<60,"50% to 60%", V3<70,"60% to 70%", V3<80,"70% to 80%", V3<90,"80% to 90%", V3<100,"90% to 100%", TRUE,"> 100%" )} -> -5% to 0% | X3: 545.55 | Y3: 546.35 | Z3: =IF(V3>0, ">0", IF(V3<0, "<0", "=0")) -> <0 | AA3: {=_xlfn.IFS( AND(O3>=0,O3<5),"0-5", AND(O3>=5,O3<15),"5-15", AND(O3>=15,O3<30),"15-30", AND(O3>=30,O3<60),"30-60", AND(O3>=60,O3<90),"60-90", AND(O3>=90,O3<120),"90-120", AND(O3>=120,O3<160),"120-160", AND(O3>=160,O3<200),"160-200", AND(O3>=200,O3<250),"200-250", AND(O3>=250,O3<300),"250-300", O3>=300,">300", TRUE,"Below 0" )} -> 0-5 | AB3: 5.52
A4: 45883 | B4: =TEXT(A4,"yyyy") -> 2025 | C4: JSW Cement Ltd | D4: =IFERROR(LEFT(C4,FIND(" ",C4)-1),C4) -> JSW | E4: =TRIM(SUBSTITUTE(SUBSTITUTE(C4,"Ltd",""),"Lt","")) -> JSW Cement | F4: =_xlfn.XLOOKUP(E4,MARKET_PRICE__2[Column2],MARKET_PRICE__2[Column3],"Not found") -> 137.85 | G4: =_xlfn.XLOOKUP(D4,MARKET_PRICE__2[Column12],MARKET_PRICE__2[Column3],"Not found") -> 307.00 | H4: 3600 | K4: =H4/10 -> 360 | N4: {=_xlfn.IFS(H4<500,"0-500",H4<1000,"500-1000",H4<1500,"1000-1500",H4<2000,"1500-2000",H4<2500,"2000-2500",H4<3000,"2500-3000",H4<3500,"3000-3500",H4<4000,"3500-4000",H4<4500,"4000-4500",H4<=5000,"4500-5000",TRUE,"Hbove 5000")} -> 3500-4000 | O4: 15.8 | P4: 10.97 | Q4: 1.81 | R4: 7.77 | S4: {=_xlfn.IFS( R4<0,"< 0", R4<5,"0 to 5", R4<10,"5 to 10", R4<15,"10 to 15", R4<20,"15 to 20", R4<25,"20 to 25", R4<50,"25 to 50", R4<75,"50 to 75", R4<100,"75 to 100", R4<125,"100 to 125", R4<150,"125 to 150", R4<175,"150 to 175", R4<200,"175 to 200", TRUE,"> 200" )} -> 5 to 10 | T4: 147 | U4: 153 | V4: 4.08 | W4: {=_xlfn.IFS( V4<-15,"< -15%", V4<-10,"-15% to -10%", V4<-5,"-10% to -5%", V4<0,"-5% to 0%", V4<10,"0% to 10%", V4<20,"10% to 20%", V4<30,"20% to 30%", V4<40,"30% to 40%", V4<50,"40% to 50%", V4<60,"50% to 60%", V4<70,"60% to 70%", V4<80,"70% to 80%", V4<90,"80% to 90%", V4<100,"90% to 100%", TRUE,"> 100%" )} -> 0% to 10% | X4: 153.15 | Y4: 153.12 | Z4: =IF(V4>0, ">0", IF(V4<0, "<0", "=0")) -> >0 | AA4: {=_xlfn.IFS( AND(O4>=0,O4<5),"0-5", AND(O4>=5,O4<15),"5-15", AND(O4>=15,O4<30),"15-30", AND(O4>=30,O4<60),"30-60", AND(O4>=60,O4<90),"60-90", AND(O4>=90,O4<120),"90-120", AND(O4>=120,O4<160),"120-160", AND(O4>=160,O4<200),"160-200", AND(O4>=200,O4<250),"200-250", AND(O4>=250,O4<300),"250-300", O4>=300,">300", TRUE,"Below 0" )} -> 15-30 | AB4: 4.18
A5: 45883 | B5: =TEXT(A5,"yyyy") -> 2025 | C5: All Time Plastics | D5: =IFERROR(LEFT(C5,FIND(" ",C5)-1),C5) -> All | E5: =TRIM(SUBSTITUTE(SUBSTITUTE(C5,"Ltd",""),"Lt","")) -> All Time Plastics | F5: =_xlfn.XLOOKUP(E5,MARKET_PRICE__2[Column2],MARKET_PRICE__2[Column3],"Not found") -> Not found | G5: =_xlfn.XLOOKUP(D5,MARKET_PRICE__2[Column12],MARKET_PRICE__2[Column3],"Not found") -> 259.55 | H5: 400.6 | I5: {=_xlfn.IFS( H5<50,"0-50", H5<100,"50-100", H5<150,"100-150", H5<200,"150-200", H5<250,"200-250", H5<300,"250-300", H5<350,"300-350", H5<400,"350-400", H5<450,"400-450", H5<=500,"450-500", TRUE,"Above 500" )} -> 400-450 | K5: =H5/10 -> 40.06 | N5: {=_xlfn.IFS(H5<500,"0-500",H5<1000,"500-1000",H5<1500,"1000-1500",H5<2000,"1500-2000",H5<2500,"2000-2500",H5<3000,"2500-3000",H5<3500,"3000-3500",H5<4000,"3500-4000",H5<4500,"4000-4500",H5<=5000,"4500-5000",TRUE,"Hbove 5000")} -> 0-500 | O5: 10.15 | P5: 13.47 | Q5: 5.14 | R5: 8.34 | S5: {=_xlfn.IFS( R5<0,"< 0", R5<5,"0 to 5", R5<10,"5 to 10", R5<15,"10 to 15", R5<20,"15 to 20", R5<25,"20 to 25", R5<50,"25 to 50", R5<75,"50 to 75", R5<100,"75 to 100", R5<125,"100 to 125", R5<150,"125 to 150", R5<175,"150 to 175", R5<200,"175 to 200", TRUE,"> 200" )} -> 5 to 10 | T5: 275 | U5: 314.3 | V5: 14.29 | W5: {=_xlfn.IFS( V5<-15,"< -15%", V5<-10,"-15% to -10%", V5<-5,"-10% to -5%", V5<0,"-5% to 0%", V5<10,"0% to 10%", V5<20,"10% to 20%", V5<30,"20% to 30%", V5<40,"30% to 40%", V5<50,"40% to 50%", V5<60,"50% to 60%", V5<70,"60% to 70%", V5<80,"70% to 80%", V5<90,"80% to 90%", V5<100,"90% to 100%", TRUE,"> 100%" )} -> 10% to 20% | X5: 315.45 | Y5: 315.25 | Z5: =IF(V5>0, ">0", IF(V5<0, "<0", "=0")) -> >0 | AA5: {=_xlfn.IFS( AND(O5>=0,O5<5),"0-5", AND(O5>=5,O5<15),"5-15", AND(O5>=15,O5<30),"15-30", AND(O5>=30,O5<60),"30-60", AND(O5>=60,O5<90),"60-90", AND(O5>=90,O5<120),"90-120", AND(O5>=120,O5<160),"120-160", AND(O5>=160,O5<200),"160-200", AND(O5>=200,O5<250),"200-250", AND(O5>=250,O5<300),"250-300", O5>=300,">300", TRUE,"Below 0" )} -> 5-15 | AB5: 14.71
A6: 45881 | B6: =TEXT(A6,"yyyy") -> 2025 | C6: Highway Infrastruc | D6: =IFERROR(LEFT(C6,FIND(" ",C6)-1),C6) -> Highway | E6: =TRIM(SUBSTITUTE(SUBSTITUTE(C6,"Ltd",""),"Lt","")) -> Highway Infrastruc | F6: =_xlfn.XLOOKUP(E6,MARKET_PRICE__2[Column2],MARKET_PRICE__2[Column3],"Not found") -> Not found | G6: =_xlfn.XLOOKUP(D6,MARKET_PRICE__2[Column12],MARKET_PRICE__2[Column3],"Not found") -> 80.01 | H6: 130 | I6: {=_xlfn.IFS( H6<50,"0-50", H6<100,"50-100", H6<150,"100-150", H6<200,"150-200", H6<250,"200-250", H6<300,"250-300", H6<350,"300-350", H6<400,"350-400", H6<450,"400-450", H6<=500,"450-500", TRUE,"Above 500" )} -> 100-150 | K6: =H6/10 -> 13 | N6: {=_xlfn.IFS(H6<500,"0-500",H6<1000,"500-1000",H6<1500,"1000-1500",H6<2000,"1500-2000",H6<2500,"2000-2500",H6<3000,"2500-3000",H6<3500,"3000-3500",H6<4000,"3500-4000",H6<4500,"4000-4500",H6<=5000,"4500-5000",TRUE,"Hbove 5000")} -> 0-500 | O6: 420.57 | P6: 447.32 | Q6: 155.58 | R6: 300.61 | S6: {=_xlfn.IFS( R6<0,"< 0", R6<5,"0 to 5", R6<10,"5 to 10", R6<15,"10 to 15", R6<20,"15 to 20", R6<25,"20 to 25", R6<50,"25 to 50", R6<75,"50 to 75", R6<100,"75 to 100", R6<125,"100 to 125", R6<150,"125 to 150", R6<175,"150 to 175", R6<200,"175 to 200", TRUE,"> 200" )} -> > 200 | T6: 70 | U6: 117 | V6: 67.14 | W6: {=_xlfn.IFS( V6<-15,"< -15%", V6<-10,"-15% to -10%", V6<-5,"-10% to -5%", V6<0,"-5% to 0%", V6<10,"0% to 10%", V6<20,"10% to 20%", V6<30,"20% to 30%", V6<40,"30% to 40%", V6<50,"40% to 50%", V6<60,"50% to 60%", V6<70,"60% to 70%", V6<80,"70% to 80%", V6<90,"80% to 90%", V6<100,"90% to 100%", TRUE,"> 100%" )} -> 60% to 70% | X6: 99.2 | Y6: 99.15 | Z6: =IF(V6>0, ">0", IF(V6<0, "<0", "=0")) -> >0 | AA6: {=_xlfn.IFS( AND(O6>=0,O6<5),"0-5", AND(O6>=5,O6<15),"5-15", AND(O6>=15,O6<30),"15-30", AND(O6>=30,O6<60),"30-60", AND(O6>=60,O6<90),"60-90", AND(O6>=90,O6<120),"90-120", AND(O6>=120,O6<160),"120-160", AND(O6>=160,O6<200),"160-200", AND(O6>=200,O6<250),"200-250", AND(O6>=250,O6<300),"250-300", O6>=300,">300", TRUE,"Below 0" )} -> >300 | AB6: 41.71
A7: 45887 | B7: =TEXT(A7,"yyyy") -> 2025 | C7: Knowledge Realty T | D7: =IFERROR(LEFT(C7,FIND(" ",C7)-1),C7) -> Knowledge | E7: =TRIM(SUBSTITUTE(SUBSTITUTE(C7,"Ltd",""),"Lt","")) -> Knowledge Realty T | F7: =_xlfn.XLOOKUP(E7,MARKET_PRICE__2[Column2],MARKET_PRICE__2[Column3],"Not found") -> Not found | G7: =_xlfn.XLOOKUP(D7,MARKET_PRICE__2[Column12],MARKET_PRICE__2[Column3],"Not found") -> 2340.00 | H7: 4800 | K7: =H7/10 -> 480 | N7: {=_xlfn.IFS(H7<500,"0-500",H7<1000,"500-1000",H7<1500,"1000-1500",H7<2000,"1500-2000",H7<2500,"2000-2500",H7<3000,"2500-3000",H7<3500,"3000-3500",H7<4000,"3500-4000",H7<4500,"4000-4500",H7<=5000,"4500-5000",TRUE,"Hbove 5000")} -> 4500-5000 | O7: 6.75 | P7: 15.51 | Q7: 0 | R7: 10.73 | S7: {=_xlfn.IFS( R7<0,"< 0", R7<5,"0 to 5", R7<10,"5 to 10", R7<15,"10 to 15", R7<20,"15 to 20", R7<25,"20 to 25", R7<50,"25 to 50", R7<75,"50 to 75", R7<100,"75 to 100", R7<125,"100 to 125", R7<150,"125 to 150", R7<175,"150 to 175", R7<200,"175 to 200", TRUE,"> 200" )} -> 10 to 15 | T7: 100 | U7: 104 | V7: 4 | W7: {=_xlfn.IFS( V7<-15,"< -15%", V7<-10,"-15% to -10%", V7<-5,"-10% to -5%", V7<0,"-5% to 0%", V7<10,"0% to 10%", V7<20,"10% to 20%", V7<30,"20% to 30%", V7<40,"30% to 40%", V7<50,"40% to 50%", V7<60,"50% to 60%", V7<70,"60% to 70%", V7<80,"70% to 80%", V7<90,"80% to 90%", V7<100,"90% to 100%", TRUE,"> 100%" )} -> 0% to 10% | X7: 107.09 | Y7: 107.06 | Z7: =IF(V7>0, ">0", IF(V7<0, "<0", "=0")) -> >0 | AA7: {=_xlfn.IFS( AND(O7>=0,O7<5),"0-5", AND(O7>=5,O7<15),"5-15", AND(O7>=15,O7<30),"15-30", AND(O7>=30,O7<60),"30-60", AND(O7>=60,O7<90),"60-90", AND(O7>=90,O7<120),"90-120", AND(O7>=120,O7<160),"120-160", AND(O7>=160,O7<200),"160-200", AND(O7>=200,O7<250),"200-250", AND(O7>=250,O7<300),"250-300", O7>=300,">300", TRUE,"Below 0" )} -> 5-15 | AB7: 7.09
A8: 45875 | B8: =TEXT(A8,"yyyy") -> 2025 | C8: M & B Engineering | D8: =IFERROR(LEFT(C8,FIND(" ",C8)-1),C8) -> M | E8: =TRIM(SUBSTITUTE(SUBSTITUTE(C8,"Ltd",""),"Lt","")) -> M & B Engineering | F8: =_xlfn.XLOOKUP(E8,MARKET_PRICE__2[Column2],MARKET_PRICE__2[Column3],"Not found") -> Not found | G8: =_xlfn.XLOOKUP(D8,MARKET_PRICE__2[Column12],MARKET_PRICE__2[Column3],"Not found") -> 64.70 | H8: 650 | J8: {=_xlfn.IFS( AND(H8>=500,H8<550),"500-550", AND(H8>=550,H8<600),"550-600", AND(H8>=600,H8<650),"600-650", AND(H8>=650,H8<700),"650-700", AND(H8>=700,H8<750),"700-750", AND(H8>=750,H8<800),"750-800", AND(H8>=800,H8<850),"800-850", AND(H8>=850,H8<900),"850-900", AND(H8>=900,H8<950),"900-950", AND(H8>=950,H8<=1000),"950-1000", H8<500,"Below 500", TRUE,"Above 1000" )} -> 650-700 | K8: {=_xlfn.IFS( AND(I8>=500,I8<550),"500-550", AND(I8>=550,I8<600),"550-600", AND(I8>=600,I8<650),"600-650", AND(I8>=650,I8<700),"650-700", AND(I8>=700,I8<750),"700-750", AND(I8>=750,I8<800),"750-800", AND(I8>=800,I8<850),"800-850", AND(I8>=850,I8<900),"850-900", AND(I8>=900,I8<950),"900-950", AND(I8>=950,I8<=1000),"950-1000", I8<500,"Below 500", TRUE,"Above 1000" )} -> Below 500 | N8: {=_xlfn.IFS(H8<500,"0-500",H8<1000,"500-1000",H8<1500,"1000-1500",H8<2000,"1500-2000",H8<2500,"2000-2500",H8<3000,"2500-3000",H8<3500,"3000-3500",H8<4000,"3500-4000",H8<4500,"4000-4500",H8<=5000,"4500-5000",TRUE,"Hbove 5000")} -> 500-1000 | O8: 36.72 | P8: 38.24 | Q8: 32.55 | R8: 36.2 | S8: {=_xlfn.IFS( R8<0,"< 0", R8<5,"0 to 5", R8<10,"5 to 10", R8<15,"10 to 15", R8<20,"15 to 20", R8<25,"20 to 25", R8<50,"25 to 50", R8<75,"50 to 75", R8<100,"75 to 100", R8<125,"100 to 125", R8<150,"125 to 150", R8<175,"150 to 175", R8<200,"175 to 200", TRUE,"> 200" )} -> 25 to 50 | T8: 385 | U8: 386 | V8: 0.26 | W8: {=_xlfn.IFS( V8<-15,"< -15%", V8<-10,"-15% to -10%", V8<-5,"-10% to -5%", V8<0,"-5% to 0%", V8<10,"0% to 10%", V8<20,"10% to 20%", V8<30,"20% to 30%", V8<40,"30% to 40%", V8<50,"40% to 50%", V8<60,"50% to 60%", V8<70,"60% to 70%", V8<80,"70% to 80%", V8<90,"80% to 90%", V8<100,"90% to 100%", TRUE,"> 100%" )} -> 0% to 10% | X8: 465.7 | Y8: 465.2 | Z8: =IF(V8>0, ">0", IF(V8<0, "<0", "=0")) -> >0 | AA8: {=_xlfn.IFS( AND(O8>=0,O8<5),"0-5", AND(O8>=5,O8<15),"5-15", AND(O8>=15,O8<30),"15-30", AND(O8>=30,O8<60),"30-60", AND(O8>=60,O8<90),"60-90", AND(O8>=90,O8<120),"90-120", AND(O8>=120,O8<160),"120-160", AND(O8>=160,O8<200),"160-200", AND(O8>=200,O8<250),"200-250", AND(O8>=250,O8<300),"250-300", O8>=300,">300", TRUE,"Below 0" )} -> 30-60 | AB8: 20.96
A9: 45875 | B9: =TEXT(A9,"yyyy") -> 2025 | C9: Sri Lotus Develope | D9: =IFERROR(LEFT(C9,FIND(" ",C9)-1),C9) -> Sri | E9: =TRIM(SUBSTITUTE(SUBSTITUTE(C9,"Ltd",""),"Lt","")) -> Sri Lotus Develope | F9: =_xlfn.XLOOKUP(E9,MARKET_PRICE__2[Column2],MARKET_PRICE__2[Column3],"Not found") -> Not found | G9: =_xlfn.XLOOKUP(D9,MARKET_PRICE__2[Column12],MARKET_PRICE__2[Column3],"Not found") -> 863.90 | H9: 792 | J9: {=_xlfn.IFS( AND(H9>=500,H9<550),"500-550", AND(H9>=550,H9<600),"550-600", AND(H9>=600,H9<650),"600-650", AND(H9>=650,H9<700),"650-700", AND(H9>=700,H9<750),"700-750", AND(H9>=750,H9<800),"750-800", AND(H9>=800,H9<850),"800-850", AND(H9>=850,H9<900),"850-900", AND(H9>=900,H9<950),"900-950", AND(H9>=950,H9<=1000),"950-1000", H9<500,"Below 500", TRUE,"Above 1000" )} -> 750-800 | K9: =H9/10 -> 79.2 | N9: {=_xlfn.IFS(H9<500,"0-500",H9<1000,"500-1000",H9<1500,"1000-1500",H9<2000,"1500-2000",H9<2500,"2000-2500",H9<3000,"2500-3000",H9<3500,"3000-3500",H9<4000,"3500-4000",H9<4500,"4000-4500",H9<=5000,"4500-5000",TRUE,"Hbove 5000")} -> 500-1000 | O9: 163.9 | P9: 57.71 | Q9: 20.28 | R9: 69.14 | S9: {=_xlfn.IFS( R9<0,"< 0", R9<5,"0 to 5", R9<10,"5 to 10", R9<15,"10 to 15", R9<20,"15 to 20", R9<25,"20 to 25", R9<50,"25 to 50", R9<75,"50 to 75", R9<100,"75 to 100", R9<125,"100 to 125", R9<150,"125 to 150", R9<175,"150 to 175", R9<200,"175 to 200", TRUE,"> 200" )} -> 50 to 75 | T9: 150 | U9: 179.1 | V9: 19.4 | W9: {=_xlfn.IFS( V9<-15,"< -15%", V9<-10,"-15% to -10%", V9<-5,"-10% to -5%", V9<0,"-5% to 0%", V9<10,"0% to 10%", V9<20,"10% to 20%", V9<30,"20% to 30%", V9<40,"30% to 40%", V9<50,"40% to 50%", V9<60,"50% to 60%", V9<70,"60% to 70%", V9<80,"70% to 80%", V9<90,"80% to 90%", V9<100,"90% to 100%", TRUE,"> 100%" )} -> 10% to 20% | X9: 192.2 | Y9: 191.81 | Z9: =IF(V9>0, ">0", IF(V9<0, "<0", "=0")) -> >0 | AA9: {=_xlfn.IFS( AND(O9>=0,O9<5),"0-5", AND(O9>=5,O9<15),"5-15", AND(O9>=15,O9<30),"15-30", AND(O9>=30,O9<60),"30-60", AND(O9>=60,O9<90),"60-90", AND(O9>=90,O9<120),"90-120", AND(O9>=120,O9<160),"120-160", AND(O9>=160,O9<200),"160-200", AND(O9>=200,O9<250),"200-250", AND(O9>=250,O9<300),"250-300", O9>=300,">300", TRUE,"Below 0" )} -> 160-200 | AB9: 28.13
A10: 45875 | B10: =TEXT(A10,"yyyy") -> 2025 | C10: National Securitie | D10: =IFERROR(LEFT(C10,FIND(" ",C10)-1),C10) -> National | E10: =TRIM(SUBSTITUTE(SUBSTITUTE(C10,"Ltd",""),"Lt","")) -> National Securitie | F10: =_xlfn.XLOOKUP(E10,MARKET_PRICE__2[Column2],MARKET_PRICE__2[Column3],"Not found") -> Not found | G10: =_xlfn.XLOOKUP(D10,MARKET_PRICE__2[Column12],MARKET_PRICE__2[Column3],"Not found") -> 244.00 | H10: 4011.6 | K10: =H10/10 -> 401.16 | N10: {=_xlfn.IFS(H10<500,"0-500",H10<1000,"500-1000",H10<1500,"1000-1500",H10<2000,"1500-2000",H10<2500,"2000-2500",H10<3000,"2500-3000",H10<3500,"3000-3500",H10<4000,"3500-4000",H10<4500,"4000-4500",H10<=5000,"4500-5000",TRUE,"Hbove 5000")} -> 4000-4500 | O10: 103.97 | P10: 34.98 | Q10: 7.73 | R10: 41.01 | S10: {=_xlfn.IFS( R10<0,"< 0", R10<5,"0 to 5", R10<10,"5 to 10", R10<15,"10 to 15", R10<20,"15 to 20", R10<25,"20 to 25", R10<50,"25 to 50", R10<75,"50 to 75", R10<100,"75 to 100", R10<125,"100 to 125", R10<150,"125 to 150", R10<175,"150 to 175", R10<200,"175 to 200", TRUE,"> 200" )} -> 25 to 50 | T10: 800 | U10: 880 | V10: 10 | W10: {=_xlfn.IFS( V10<-15,"< -15%", V10<-10,"-15% to -10%", V10<-5,"-10% to -5%", V10<0,"-5% to 0%", V10<10,"0% to 10%", V10<20,"10% to 20%", V10<30,"20% to 30%", V10<40,"30% to 40%", V10<50,"40% to 50%", V10<60,"50% to 60%", V10<70,"60% to 70%", V10<80,"70% to 80%", V10<90,"80% to 90%", V10<100,"90% to 100%", TRUE,"> 100%" )} -> 10% to 20% | X10: 1275.4 | Z10: =IF(V10>0, ">0", IF(V10<0, "<0", "=0")) -> >0 | AA10: {=_xlfn.IFS( AND(O10>=0,O10<5),"0-5", AND(O10>=5,O10<15),"5-15", AND(O10>=15,O10<30),"15-30", AND(O10>=30,O10<60),"30-60", AND(O10>=60,O10<90),"60-90", AND(O10>=90,O10<120),"90-120", AND(O10>=120,O10<160),"120-160", AND(O10>=160,O10<200),"160-200", AND(O10>=200,O10<250),"200-250", AND(O10>=250,O10<300),"250-300", O10>=300,">300", TRUE,"Below 0" )} -> 90-120 | AB10: 59.43
A11: 45874 | B11: =TEXT(A11,"yyyy") -> 2025 | C11: Aditya Infotech Lt | D11: =IFERROR(LEFT(C11,FIND(" ",C11)-1),C11) -> Aditya | E11: =TRIM(SUBSTITUTE(SUBSTITUTE(C11,"Ltd",""),"Lt","")) -> Aditya Infotech | F11: =_xlfn.XLOOKUP(E11,MARKET_PRICE__2[Column2],MARKET_PRICE__2[Column3],"Not found") -> 1354.50 | G11: =_xlfn.XLOOKUP(D11,MARKET_PRICE__2[Column12],MARKET_PRICE__2[Column3],"Not found") -> 804.45 | H11: 1300 | K11: =H11/10 -> 130 | N11: {=_xlfn.IFS(H11<500,"0-500",H11<1000,"500-1000",H11<1500,"1000-1500",H11<2000,"1500-2000",H11<2500,"2000-2500",H11<3000,"2500-3000",H11<3500,"3000-3500",H11<4000,"3500-4000",H11<4500,"4000-4500",H11<=5000,"4500-5000",TRUE,"Hbove 5000")} -> 1000-1500 | O11: 133.21 | P11: 72 | Q11: 50.87 | R11: 100.69 | S11: {=_xlfn.IFS( R11<0,"< 0", R11<5,"0 to 5", R11<10,"5 to 10", R11<15,"10 to 15", R11<20,"15 to 20", R11<25,"20 to 25", R11<50,"25 to 50", R11<75,"50 to 75", R11<100,"75 to 100", R11<125,"100 to 125", R11<150,"125 to 150", R11<175,"150 to 175", R11<200,"175 to 200", TRUE,"> 200" )} -> 100 to 125 | T11: 675 | U11: 1018 | V11: 50.81 | W11: {=_xlfn.IFS( V11<-15,"< -15%", V11<-10,"-15% to -10%", V11<-5,"-10% to -5%", V11<0,"-5% to 0%", V11<10,"0% to 10%", V11<20,"10% to 20%", V11<30,"20% to 30%", V11<40,"30% to 40%", V11<50,"40% to 50%", V11<60,"50% to 60%", V11<70,"60% to 70%", V11<80,"70% to 80%", V11<90,"80% to 90%", V11<100,"90% to 100%", TRUE,"> 100%" )} -> 50% to 60% | X11: 1361.1 | Y11: 1360.45 | Z11: =IF(V11>0, ">0", IF(V11<0, "<0", "=0")) -> >0 | AA11: {=_xlfn.IFS( AND(O11>=0,O11<5),"0-5", AND(O11>=5,O11<15),"5-15", AND(O11>=15,O11<30),"15-30", AND(O11>=30,O11<60),"30-60", AND(O11>=60,O11<90),"60-90", AND(O11>=90,O11<120),"90-120", AND(O11>=120,O11<160),"120-160", AND(O11>=160,O11<200),"160-200", AND(O11>=200,O11<250),"200-250", AND(O11>=250,O11<300),"250-300", O11>=300,">300", TRUE,"Below 0" )} -> 120-160 | AB11: 101.64
A12: 45874 | B12: =TEXT(A12,"yyyy") -> 2025 | C12: Laxmi India Financ | D12: =IFERROR(LEFT(C12,FIND(" ",C12)-1),C12) -> Laxmi | E12: =TRIM(SUBSTITUTE(SUBSTITUTE(C12,"Ltd",""),"Lt","")) -> Laxmi India Financ | F12: =_xlfn.XLOOKUP(E12,MARKET_PRICE__2[Column2],MARKET_PRICE__2[Column3],"Not found") -> Not found | G12: =_xlfn.XLOOKUP(D12,MARKET_PRICE__2[Column12],MARKET_PRICE__2[Column3],"Not found") -> 320.00 | H12: 254.26 | I12: {=_xlfn.IFS( H12<50,"0-50", H12<100,"50-100", H12<150,"100-150", H12<200,"150-200", H12<250,"200-250", H12<300,"250-300", H12<350,"300-350", H12<400,"350-400", H12<450,"400-450", H12<=500,"450-500", TRUE,"Above 500" )} -> 250-300 | K12: =H12/10 -> 25.426 | N12: {=_xlfn.IFS(H12<500,"0-500",H12<1000,"500-1000",H12<1500,"1000-1500",H12<2000,"1500-2000",H12<2500,"2000-2500",H12<3000,"2500-3000",H12<3500,"3000-3500",H12<4000,"3500-4000",H12<4500,"4000-4500",H12<=5000,"4500-5000",TRUE,"Hbove 5000")} -> 0-500 | O12: 1.3 | P12: 1.84 | Q12: 2.22 | R12: 1.87 | S12: {=_xlfn.IFS( R12<0,"< 0", R12<5,"0 to 5", R12<10,"5 to 10", R12<15,"10 to 15", R12<20,"15 to 20", R12<25,"20 to 25", R12<50,"25 to 50", R12<75,"50 to 75", R12<100,"75 to 100", R12<125,"100 to 125", R12<150,"125 to 150", R12<175,"150 to 175", R12<200,"175 to 200", TRUE,"> 200" )} -> 0 to 5 | T12: 158 | U12: 136 | V12: -13.92 | W12: {=_xlfn.IFS( V12<-15,"< -15%", V12<-10,"-15% to -10%", V12<-5,"-10% to -5%", V12<0,"-5% to 0%", V12<10,"0% to 10%", V12<20,"10% to 20%", V12<30,"20% to 30%", V12<40,"30% to 40%", V12<50,"40% to 50%", V12<60,"50% to 60%", V12<70,"60% to 70%", V12<80,"70% to 80%", V12<90,"80% to 90%", V12<100,"90% to 100%", TRUE,"> 100%" )} -> -15% to -10% | X12: 140.75 | Y12: 141.13 | Z12: =IF(V12>0, ">0", IF(V12<0, "<0", "=0")) -> <0 | AA12: {=_xlfn.IFS( AND(O12>=0,O12<5),"0-5", AND(O12>=5,O12<15),"5-15", AND(O12>=15,O12<30),"15-30", AND(O12>=30,O12<60),"30-60", AND(O12>=60,O12<90),"60-90", AND(O12>=90,O12<120),"90-120", AND(O12>=120,O12<160),"120-160", AND(O12>=160,O12<200),"160-200", AND(O12>=200,O12<250),"200-250", AND(O12>=250,O12<300),"250-300", O12>=300,">300", TRUE,"Below 0" )} -> 0-5 | AB12: -10.92
A13: 45870 | B13: =TEXT(A13,"yyyy") -> 2025 | C13: Shanti Gold Intern | D13: =IFERROR(LEFT(C13,FIND(" ",C13)-1),C13) -> Shanti | E13: =TRIM(SUBSTITUTE(SUBSTITUTE(C13,"Ltd",""),"Lt","")) -> Shanti Gold Intern | F13: =_xlfn.XLOOKUP(E13,MARKET_PRICE__2[Column2],MARKET_PRICE__2[Column3],"Not found") -> Not found | G13: =_xlfn.XLOOKUP(D13,MARKET_PRICE__2[Column12],MARKET_PRICE__2[Column3],"Not found") -> 210.00 | H13: 360.11 | I13: {=_xlfn.IFS( H13<50,"0-50", H13<100,"50-100", H13<150,"100-150", H13<200,"150-200", H13<250,"200-250", H13<300,"250-300", H13<350,"300-350", H13<400,"350-400", H13<450,"400-450", H13<=500,"450-500", TRUE,"Above 500" )} -> 350-400 | K13: =H13/10 -> 36.011 | N13: {=_xlfn.IFS(H13<500,"0-500",H13<1000,"500-1000",H13<1500,"1000-1500",H13<2000,"1500-2000",H13<2500,"2000-2500",H13<3000,"2500-3000",H13<3500,"3000-3500",H13<4000,"3500-4000",H13<4500,"4000-4500",H13<=5000,"4500-5000",TRUE,"Hbove 5000")} -> 0-500 | O13: 117.33 | P13: 151.48 | Q13: 30.37 | R13: 81.17 | S13: {=_xlfn.IFS( R13<0,"< 0", R13<5,"0 to 5", R13<10,"5 to 10", R13<15,"10 to 15", R13<20,"15 to 20", R13<25,"20 to 25", R13<50,"25 to 50", R13<75,"50 to 75", R13<100,"75 to 100", R13<125,"100 to 125", R13<150,"125 to 150", R13<175,"150 to 175", R13<200,"175 to 200", TRUE,"> 200" )} -> 75 to 100 | T13: 199 | U13: 229.1 | V13: 15.13 | W13: {=_xlfn.IFS( V13<-15,"< -15%", V13<-10,"-15% to -10%", V13<-5,"-10% to -5%", V13<0,"-5% to 0%", V13<10,"0% to 10%", V13<20,"10% to 20%", V13<30,"20% to 30%", V13<40,"30% to 40%", V13<50,"40% to 50%", V13<60,"50% to 60%", V13<70,"60% to 70%", V13<80,"70% to 80%", V13<90,"80% to 90%", V13<100,"90% to 100%", TRUE,"> 100%" )} -> 10% to 20% | X13: 246.25 | Y13: 246.22 | Z13: =IF(V13>0, ">0", IF(V13<0, "<0", "=0")) -> >0 | AA13: {=_xlfn.IFS( AND(O13>=0,O13<5),"0-5", AND(O13>=5,O13<15),"5-15", AND(O13>=15,O13<30),"15-30", AND(O13>=30,O13<60),"30-60", AND(O13>=60,O13<90),"60-90", AND(O13>=90,O13<120),"90-120", AND(O13>=120,O13<160),"120-160", AND(O13>=160,O13<200),"160-200", AND(O13>=200,O13<250),"200-250", AND(O13>=250,O13<300),"250-300", O13>=300,">300", TRUE,"Below 0" )} -> 90-120 | AB13: 23.74
A14: 45869 | B14: =TEXT(A14,"yyyy") -> 2025 | C14: Brigade Hotel Vent | D14: =IFERROR(LEFT(C14,FIND(" ",C14)-1),C14) -> Brigade | E14: =TRIM(SUBSTITUTE(SUBSTITUTE(C14,"Ltd",""),"Lt","")) -> Brigade Hotel Vent | F14: =_xlfn.XLOOKUP(E14,MARKET_PRICE__2[Column2],MARKET_PRICE__2[Column3],"Not found") -> Not found | G14: =_xlfn.XLOOKUP(D14,MARKET_PRICE__2[Column12],MARKET_PRICE__2[Column3],"Not found") -> 81.05 | H14: 759.6 | J14: {=_xlfn.IFS( AND(H14>=500,H14<550),"500-550", AND(H14>=550,H14<600),"550-600", AND(H14>=600,H14<650),"600-650", AND(H14>=650,H14<700),"650-700", AND(H14>=700,H14<750),"700-750", AND(H14>=750,H14<800),"750-800", AND(H14>=800,H14<850),"800-850", AND(H14>=850,H14<900),"850-900", AND(H14>=900,H14<950),"900-950", AND(H14>=950,H14<=1000),"950-1000", H14<500,"Below 500", TRUE,"Above 1000" )} -> 750-800 | K14: =H14/10 -> 75.96 | N14: {=_xlfn.IFS(H14<500,"0-500",H14<1000,"500-1000",H14<1500,"1000-1500",H14<2000,"1500-2000",H14<2500,"2000-2500",H14<3000,"2500-3000",H14<3500,"3000-3500",H14<4000,"3500-4000",H14<4500,"4000-4500",H14<=5000,"4500-5000",TRUE,"Hbove 5000")} -> 500-1000 | O14: 5.42 | P14: 1.92 | Q14: 6.4 | R14: 4.48 | S14: {=_xlfn.IFS( R14<0,"< 0", R14<5,"0 to 5", R14<10,"5 to 10", R14<15,"10 to 15", R14<20,"15 to 20", R14<25,"20 to 25", R14<50,"25 to 50", R14<75,"50 to 75", R14<100,"75 to 100", R14<125,"100 to 125", R14<150,"125 to 150", R14<175,"150 to 175", R14<200,"175 to 200", TRUE,"> 200" )} -> 0 to 5 | T14: 90 | U14: 82 | V14: -8.89 | W14: {=_xlfn.IFS( V14<-15,"< -15%", V14<-10,"-15% to -10%", V14<-5,"-10% to -5%", V14<0,"-5% to 0%", V14<10,"0% to 10%", V14<20,"10% to 20%", V14<30,"20% to 30%", V14<40,"30% to 40%", V14<50,"40% to 50%", V14<60,"50% to 60%", V14<70,"60% to 70%", V14<80,"70% to 80%", V14<90,"80% to 90%", V14<100,"90% to 100%", TRUE,"> 100%" )} -> -10% to -5% | X14: 86.34 | Y14: 86.35 | Z14: =IF(V14>0, ">0", IF(V14<0, "<0", "=0")) -> <0 | AA14: {=_xlfn.IFS( AND(O14>=0,O14<5),"0-5", AND(O14>=5,O14<15),"5-15", AND(O14>=15,O14<30),"15-30", AND(O14>=30,O14<60),"30-60", AND(O14>=60,O14<90),"60-90", AND(O14>=90,O14<120),"90-120", AND(O14>=120,O14<160),"120-160", AND(O14>=160,O14<200),"160-200", AND(O14>=200,O14<250),"200-250", AND(O14>=250,O14<300),"250-300", O14>=300,">300", TRUE,"Below 0" )} -> 5-15 | AB14: -4.07
A15: 45868 | B15: =TEXT(A15,"yyyy") -> 2025 | C15: GNG Electronics Lt | D15: =IFERROR(LEFT(C15,FIND(" ",C15)-1),C15) -> GNG | E15: =TRIM(SUBSTITUTE(SUBSTITUTE(C15,"Ltd",""),"Lt","")) -> GNG Electronics | F15: =_xlfn.XLOOKUP(E15,MARKET_PRICE__2[Column2],MARKET_PRICE__2[Column3],"Not found") -> 344.00 | G15: =_xlfn.XLOOKUP(D15,MARKET_PRICE__2[Column12],MARKET_PRICE__2[Column3],"Not found") -> 344.00 | H15: 460.44 | I15: {=_xlfn.IFS( H15<50,"0-50", H15<100,"50-100", H15<150,"100-150", H15<200,"150-200", H15<250,"200-250", H15<300,"250-300", H15<350,"300-350", H15<400,"350-400", H15<450,"400-450", H15<=500,"450-500", TRUE,"Above 500" )} -> 450-500 | K15: =H15/10 -> 46.044 | N15: {=_xlfn.IFS(H15<500,"0-500",H15<1000,"500-1000",H15<1500,"1000-1500",H15<2000,"1500-2000",H15<2500,"2000-2500",H15<3000,"2500-3000",H15<3500,"3000-3500",H15<4000,"3500-4000",H15<4500,"4000-4500",H15<=5000,"4500-5000",TRUE,"Hbove 5000")} -> 0-500 | O15: 266.21 | P15: 227.67 | Q15: 46.84 | R15: 147.93 | S15: {=_xlfn.IFS( R15<0,"< 0", R15<5,"0 to 5", R15<10,"5 to 10", R15<15,"10 to 15", R15<20,"15 to 20", R15<25,"20 to 25", R15<50,"25 to 50", R15<75,"50 to 75", R15<100,"75 to 100", R15<125,"100 to 125", R15<150,"125 to 150", R15<175,"150 to 175", R15<200,"175 to 200", TRUE,"> 200" )} -> 125 to 150 | T15: 237 | U15: 350 | V15: 47.68 | W15: {=_xlfn.IFS( V15<-15,"< -15%", V15<-10,"-15% to -10%", V15<-5,"-10% to -5%", V15<0,"-5% to 0%", V15<10,"0% to 10%", V15<20,"10% to 20%", V15<30,"20% to 30%", V15<40,"30% to 40%", V15<50,"40% to 50%", V15<60,"50% to 60%", V15<70,"60% to 70%", V15<80,"70% to 80%", V15<90,"80% to 90%", V15<100,"90% to 100%", TRUE,"> 100%" )} -> 40% to 50% | X15: 345.3 | Y15: 344.85 | Z15: =IF(V15>0, ">0", IF(V15<0, "<0", "=0")) -> >0 | AA15: {=_xlfn.IFS( AND(O15>=0,O15<5),"0-5", AND(O15>=5,O15<15),"5-15", AND(O15>=15,O15<30),"15-30", AND(O15>=30,O15<60),"30-60", AND(O15>=60,O15<90),"60-90", AND(O15>=90,O15<120),"90-120", AND(O15>=120,O15<160),"120-160", AND(O15>=160,O15<200),"160-200", AND(O15>=200,O15<250),"200-250", AND(O15>=250,O15<300),"250-300", O15>=300,">300", TRUE,"Below 0" )} -> 250-300 | AB15: 45.7
